File: data/Cr2p-dots_images.vms
VAMAS Surface Chemical Analysis Standard Data Transfer Format 1988 May 4
Not Specified
Not Specified
Not Specified
Not Specified
3
Casa Info Follows CasaXPS Version 2.3.19PR1.0
0
SourceAnalyserAngle: Not Specified
MAPSV
MAPPING
1
Exp Variable
d
0
0
0
0
38
Cr 2p/40
images-of-Cr-dots.vms
2003
9
26
19
8
28
0
10
Casa Info Follows
0
0
0
0
   Lens Mode:Field of View 2: Small Spot   Resolution:Pass energy 80    Anode:Mono(Al (Mono))(300 W)
   Energy(eV): 909.590    Dwell(ms): 300000     Sweeps: 1        Acquisition Time(s): 19660800
   Acquired On :03/09/26 19:08:28   C/N :On

C:\Users\mfl\Documents\XPS\PCA-presentation\demodata CasaXPS\images-of-Cr-dots.vms
XPS
577.1
Mono(Al (Mono))
1486.69
300
1e+037
1e+037
221
221
1
1
128
1
128
128
1e+037
1e+037
FAT
80
1e+037
-4.913
0
1e+037
1e+037
1e+037
1e+037
Cr
2p
-1
1
Intensity
d
analogue
300
4
0
1e+037
1e+037
1e+037
1
MFP Exponent
d
0
255
216
256
195
112
161
193
130
160
246
210
227
135
135
217
163
206
158
139
145
150
213
110
159
171
160
140
128
180
144
108
123
249
174
132
188
137
259
222
159
134
147
137
186
171
143
169
131
136
162
158
181
146
89
154
198
178
168
200
145
199
196
193
217
166
79
132
251
119
140
127
217
306
166
228
250
190
89
172
299
130
156
143
184
195
162
199
125
149
76
255
228
157
146
145
243
269
125
213
175
133
76
177
131
83
175
164
197
178
169
198
157
157
192
274
118
77
118
223
294
170
125
199
157
92
199
188
178
129
154
216
196
177
186
181
89
87
254
137
234
106
217
235
200
155
163
129
129
149
167
129
148
83
134
234
171
169
200
85
100
154
123
125
204
82
353
174
154
214
220
143
64
152
125
182
89
93
245
168
108
134
146
128
166
138
147
141
85
184
120
158
160
124
120
132
118
169
94
169
113
198
142
191
128
82
141
110
160
138
195
71
161
162
175
132
155
136
124
157
148
114
197
78
215
172
132
99
112
103
144
156
127
131
139
104
202
160
109
166
156
83
105
146
158
171
134
131
163
118
131
106
135
152
182
132
97
203
61
131
121
199
132
144
104
104
140
170
227
145
142
158
215
114
122
87
211
147
192
116
158
95
190
139
173
106
137
171
138
112
150
141
147
93
248
164
182
133
153
168
147
130
102
152
130
160
156
145
98
124
113
155
155
94
153
125
107
166
129
139
176
111
75
129
146
184
110
119
88
200
161
196
182
143
181
205
129
147
217
147
206
184
195
157
114
119
174
170
204
155
170
123
177
273
130
147
133
100
190
135
280
98
134
196
234
232
199
213
113
198
218
113
172
205
196
230
254
164
234
157
125
206
111
264
112
213
145
244
304
189
176
140
142
185
143
268
217
196
256
187
225
223
132
113
163
153
143
204
189
162
202
291
171
220
121
108
149
202
175
183
225
217
253
277
192
189
156
180
291
185
112
165
230
192
274
234
206
202
93
191
136
177
124
254
125
232
227
130
218
132
125
166
183
150
164
249
180
199
299
163
166
114
109
194
186
114
118
215
119
206
211
253
208
151
147
129
193
154
250
151
191
222
175
224
164
159
144
159
105
97
181
218
226
233
187
168
130
98
143
168
164
175
214
186
239
267
156
152
157
150
95
117
114
167
123
195
230
150
153
149
177
137
160
153
191
203
120
209
189
148
126
143
135
166
185
158
172
154
167
269
136
141
94
73
112
231
135
127
158
227
124
210
141
161
177
133
184
108
141
151
141
151
122
193
143
122
111
143
118
215
107
132
120
162
203
142
141
101
139
198
123
149
136
192
170
155
106
134
184
120
130
167
118
86
197
115
162
190
247
126
166
155
110
135
163
111
158
120
180
194
192
132
142
123
197
162
200
130
194
174
139
143
175
144
109
115
226
213
166
137
149
138
188
190
158
157
130
154
163
156
106
166
192
137
167
209
129
142
121
190
164
187
170
131
187
149
109
154
158
156
140
197
145
122
172
97
165
162
135
129
189
217
165
153
175
163
172
111
135
76
181
143
166
214
216
166
270
183
164
132
163
173
199
182
141
155
195
132
226
154
172
123
125
112
164
233
185
254
196
143
119
126
132
181
107
136
163
228
204
228
173
164
223
208
74
151
119
298
160
234
228
221
148
93
145
147
139
118
138
198
254
269
165
200
145
188
314
180
219
140
157
137
157
143
193
174
169
177
230
148
182
96
214
166
138
174
230
188
111
131
110
178
131
93
118
98
141
226
238
115
265
196
121
216
186
99
83
169
129
184
164
197
106
238
85
155
126
91
135
155
157
157
180
181
153
140
200
162
122
146
114
150
166
127
168
226
200
166
192
184
153
137
106
199
146
149
122
188
260
126
188
141
117
131
103
159
91
137
151
183
190
190
119
126
85
113
99
154
220
157
141
120
140
206
151
138
131
92
177
155
220
150
99
191
161
190
92
109
70
77
153
184
180
85
126
164
177
145
125
132
150
135
145
174
151
132
170
98
152
101
139
129
137
186
113
165
157
160
142
123
112
150
80
134
188
190
139
147
220
162
169
173
112
167
76
116
197
95
198
163
187
162
164
171
196
134
102
106
178
178
106
145
210
163
185
131
108
154
97
179
111
131
155
162
221
156
169
164
134
113
103
188
139
100
158
196
140
200
147
147
79
114
133
163
216
153
139
132
155
186
109
111
100
99
186
156
145
124
164
167
153
259
126
97
85
60
136
178
105
134
152
143
184
162
109
115
145
78
147
139
185
83
214
175
166
152
85
91
96
166
137
127
160
167
180
192
163
108
116
108
145
117
149
126
111
210
159
179
124
144
73
101
161
135
107
117
208
191
122
131
137
109
102
124
231
141
163
162
185
184
162
86
125
108
96
81
189
150
152
118
163
177
140
159
104
212
104
130
143
122
117
140
169
121
192
121
72
142
101
179
143
102
151
167
157
186
114
138
117
108
118
126
123
138
127
172
143
102
117
129
125
157
111
130
216
168
187
161
161
187
128
114
84
137
226
170
173
163
177
128
135
110
108
118
98
158
160
178
183
102
156
176
198
130
138
125
141
140
156
250
218
156
159
151
190
70
108
100
192
200
199
156
166
138
160
220
174
123
96
122
168
169
235
177
168
122
140
155
128
79
140
262
175
210
221
144
143
141
145
180
132
143
135
291
173
221
284
86
199
145
133
186
224
108
166
283
162
186
268
190
169
160
168
123
94
107
184
195
191
259
154
219
211
130
140
199
132
170
191
187
237
153
114
176
113
169
137
125
128
217
204
185
305
183
234
278
129
110
202
115
144
180
285
203
220
174
244
171
154
192
175
86
226
260
150
258
225
130
294
152
124
207
154
121
231
318
213
199
175
232
237
202
185
172
97
150
246
186
241
247
186
244
229
191
312
196
110
151
284
174
197
199
252
231
165
127
239
151
132
243
278
179
240
233
213
211
159
195
198
157
86
255
231
238
227
194
305
201
132
170
180
80
167
216
181
323
224
205
205
175
230
199
153
114
187
281
188
260
148
151
193
138
199
136
64
178
280
160
242
250
158
228
285
110
288
175
117
200
272
163
263
179
255
181
129
85
214
157
186
250
233
114
198
125
228
209
107
184
122
105
158
277
133
183
214
112
201
259
109
183
143
113
232
200
160
217
106
290
239
95
106
208
97
181
255
179
159
271
164
228
243
107
144
164
120
178
264
195
164
204
277
209
137
106
144
126
121
231
136
181
184
110
248
133
198
112
117
78
83
199
163
207
199
151
255
122
102
114
142
94
158
168
164
136
109
154
277
126
133
122
70
95
148
144
189
130
119
191
171
132
93
122
125
120
210
159
210
182
107
136
92
113
112
85
89
93
161
203
108
106
80
Cr 2p/41
images-of-Cr-dots.vms
2003
9
26
19
8
28
0
10
Casa Info Follows
0
0
0
0
   Lens Mode:Field of View 2: Small Spot   Resolution:Pass energy 80    Anode:Mono(Al (Mono))(300 W)
   Energy(eV): 909.890    Dwell(ms): 300000     Sweeps: 1        Acquisition Time(s): 19660800
   Acquired On :03/09/26 19:08:28   C/N :On

C:\Users\mfl\Documents\XPS\PCA-presentation\demodata CasaXPS\images-of-Cr-dots.vms
XPS
576.8
Mono(Al (Mono))
1486.69
300
1e+037
1e+037
221
221
1
1
128
1
128
128
1e+037
1e+037
FAT
80
1e+037
-4.913
0
1e+037
1e+037
1e+037
1e+037
Cr
2p
-1
1
Intensity
d
analogue
300
4
0
1e+037
1e+037
1e+037
1
MFP Exponent
d
0
188
123
267
254
170
168
179
165
147
218
200
214
162
99
325
140
177
145
154
158
148
210
172
204
139
231
199
171
181
209
165
127
167
165
141
196
177
217
142
166
178
138
83
149
196
206
96
126
118
190
188
176
144
113
104
196
177
128
198
160
246
133
95
157
185
86
113
227
188
139
225
141
223
206
162
185
127
119
140
190
168
146
110
180
219
162
112
205
112
154
236
229
212
151
160
166
139
125
187
204
102
139
220
153
106
156
196
233
147
135
131
146
170
155
198
169
90
82
211
245
97
213
207
83
63
160
235
146
181
109
252
181
148
184
160
101
112
223
172
173
83
113
181
204
182
176
179
107
165
113
134
140
77
196
201
191
164
178
150
128
123
146
152
160
110
291
162
174
150
216
143
162
162
137
234
143
149
248
214
134
173
154
97
170
144
147
181
84
199
125
153
139
175
153
169
129
177
184
158
92
187
172
117
111
133
138
130
120
142
222
123
155
168
182
114
93
102
120
101
153
140
202
67
211
126
192
101
79
140
126
136
213
101
109
92
163
116
166
122
112
144
187
147
147
146
118
133
208
168
205
104
169
85
145
207
129
150
93
114
160
113
103
120
104
145
157
143
251
128
84
144
200
161
161
83
100
140
111
150
143
126
143
162
202
114
125
158
105
139
137
99
197
94
121
146
177
155
162
135
127
151
141
90
118
178
214
162
194
148
150
102
192
165
191
170
98
225
164
128
131
95
191
201
155
202
118
227
150
206
225
161
213
161
118
241
138
210
124
137
195
249
178
226
159
104
119
98
192
150
178
127
199
200
218
230
133
88
209
130
177
104
118
139
264
234
186
178
137
226
209
132
202
165
162
204
321
133
171
160
128
240
142
226
147
190
138
233
300
275
146
138
182
223
164
190
213
170
214
207
217
263
169
111
134
198
156
236
220
170
199
273
170
241
101
146
165
203
193
165
266
118
234
219
150
214
100
192
217
164
206
148
219
210
280
194
254
171
122
117
140
205
121
289
127
168
235
121
275
151
107
167
116
114
133
213
150
176
242
224
175
96
135
109
126
148
161
207
135
293
162
245
151
197
147
144
221
163
291
182
239
241
134
203
143
175
148
188
141
139
229
202
225
207
136
173
147
167
141
133
146
155
207
229
258
157
158
120
117
223
195
119
116
200
136
214
305
155
164
110
100
148
143
118
227
148
167
180
184
106
125
172
154
127
150
172
229
194
197
220
139
125
83
131
112
138
100
111
154
143
183
197
149
143
178
157
141
133
147
219
176
264
187
183
157
163
150
186
193
177
133
181
184
99
172
159
122
122
126
146
162
133
163
214
182
178
151
126
149
96
84
187
171
117
163
199
191
144
141
152
144
177
114
173
204
137
120
147
158
222
185
115
127
119
139
200
182
69
193
216
131
165
140
142
124
118
238
184
221
123
163
210
126
134
96
146
126
147
194
138
136
115
150
104
135
123
172
165
102
210
149
205
217
171
154
152
61
99
167
170
121
155
139
223
123
163
145
103
98
175
150
138
164
143
193
185
171
150
146
177
158
161
138
210
249
137
243
178
150
114
186
84
230
193
114
185
220
137
187
165
159
91
134
156
171
257
229
157
133
203
166
281
128
151
126
170
130
132
176
217
189
202
151
205
148
203
73
263
164
159
202
143
193
151
134
119
88
134
69
122
157
207
153
157
93
51
293
119
219
122
164
145
147
190
171
176
156
152
174
130
204
81
142
173
126
165
206
202
104
231
151
203
121
106
141
156
151
216
176
147
288
237
114
167
171
166
142
142
134
198
142
154
81
224
108
107
99
121
154
129
156
170
162
128
165
120
184
182
125
126
161
173
164
127
150
163
202
95
232
137
125
99
104
170
130
193
158
144
188
138
115
152
131
114
145
186
207
141
132
136
151
130
113
99
69
93
112
186
154
179
119
204
227
189
136
143
112
140
170
180
129
157
124
202
150
157
142
126
75
84
158
136
161
89
112
225
140
134
137
115
148
119
220
168
116
197
199
148
168
164
131
142
195
170
156
195
124
146
130
156
116
102
84
70
166
155
186
115
236
150
135
122
119
114
79
142
169
105
158
148
143
244
122
136
154
89
121
195
211
161
128
108
152
205
171
117
108
81
108
110
208
212
177
136
210
145
203
208
143
82
90
180
191
137
146
203
174
209
142
151
95
78
141
167
130
126
104
223
199
176
176
101
152
85
147
156
126
180
166
151
127
246
180
77
151
90
109
174
158
150
117
188
157
176
111
169
135
123
142
142
123
131
243
113
218
134
123
100
101
165
140
147
114
210
125
149
198
140
92
93
98
114
153
111
188
184
159
166
91
109
88
67
121
191
112
138
241
233
157
125
156
117
88
77
175
180
106
125
210
145
131
194
79
142
90
113
157
88
178
117
127
92
155
187
160
93
85
96
174
184
127
135
187
134
124
111
102
114
157
96
186
172
145
181
180
236
162
127
152
131
159
169
141
145
121
179
180
149
126
88
115
113
187
168
181
140
151
158
197
115
106
103
50
145
256
133
238
126
125
174
147
117
119
130
128
142
149
133
188
72
166
140
157
142
88
135
139
121
143
155
209
197
177
185
147
72
136
199
156
173
220
194
95
174
165
238
147
120
113
175
198
140
188
205
182
138
94
177
177
120
102
174
204
170
282
192
134
182
163
182
111
124
139
276
168
195
240
163
125
132
147
253
184
189
235
319
150
262
186
221
186
196
166
196
83
129
158
156
209
144
218
275
230
140
170
150
155
164
194
197
273
251
152
220
172
154
187
208
117
224
281
156
314
247
164
248
135
143
173
145
141
226
182
324
165
172
295
177
190
203
167
118
183
226
162
227
268
63
240
178
184
213
182
147
221
232
206
256
190
233
235
187
210
162
83
168
325
181
291
279
269
201
200
164
262
153
103
150
233
193
241
242
332
238
137
119
214
83
158
198
237
188
155
231
205
275
171
209
293
120
91
283
201
230
298
182
258
221
153
271
151
120
164
243
229
262
125
234
217
150
119
155
193
125
163
145
245
299
176
297
210
178
208
201
131
175
306
137
253
233
172
269
158
174
185
147
73
244
321
218
266
204
273
214
139
136
189
124
109
178
226
245
246
162
170
141
120
162
216
86
182
320
175
183
175
118
252
191
95
220
211
127
187
171
188
232
191
262
211
100
107
146
131
114
203
120
185
195
164
267
228
163
160
117
119
233
202
130
245
150
223
206
94
116
184
105
77
182
197
139
156
107
207
205
151
122
128
75
111
198
168
188
174
135
202
226
131
133
108
72
133
148
154
149
143
135
139
118
127
109
88
98
117
260
138
160
132
261
127
112
114
116
116
127
166
173
206
159
97
187
141
106
67
79
87
125
127
177
181
79
81
Cr 2p/42
images-of-Cr-dots.vms
2003
9
26
19
8
28
0
10
Casa Info Follows
0
0
0
0
   Lens Mode:Field of View 2: Small Spot   Resolution:Pass energy 80    Anode:Mono(Al (Mono))(300 W)
   Energy(eV): 910.190    Dwell(ms): 300000     Sweeps: 1        Acquisition Time(s): 19660800
   Acquired On :03/09/26 19:08:28   C/N :On

C:\Users\mfl\Documents\XPS\PCA-presentation\demodata CasaXPS\images-of-Cr-dots.vms
XPS
576.5
Mono(Al (Mono))
1486.69
300
1e+037
1e+037
221
221
1
1
128
1
128
128
1e+037
1e+037
FAT
80
1e+037
-4.913
0
1e+037
1e+037
1e+037
1e+037
Cr
2p
-1
1
Intensity
d
analogue
300
4
0
1e+037
1e+037
1e+037
1
MFP Exponent
d
0
167
198
274
236
137
166
198
153
198
257
231
263
135
132
214
149
171
165
153
110
192
181
99
225
139
230
174
187
134
178
142
182
286
185
149
211
115
210
152
127
179
145
161
249
224
204
151
119
165
228
236
209
133
145
118
171
232
133
156
136
201
198
169
166
196
108
113
204
174
136
191
177
189
168
162
192
153
113
176
157
108
137
169
177
176
163
188
170
163
112
179
241
104
145
101
304
253
116
182
136
91
159
200
197
93
138
161
168
170
130
202
131
116
141
263
195
118
100
202
216
214
189
226
103
123
197
138
156
119
133
233
216
117
155
201
83
81
185
168
236
137
119
230
194
134
158
120
116
150
189
176
144
85
203
168
142
157
215
118
118
171
190
198
169
75
214
196
134
144
130
96
85
142
147
271
76
118
162
177
190
146
115
108
197
157
145
194
109
213
211
160
96
141
112
106
136
142
156
126
96
271
212
124
131
136
91
146
119
143
180
165
188
161
175
124
105
75
114
105
144
146
172
105
165
107
169
167
138
55
114
173
130
136
124
80
118
116
196
182
57
168
127
136
229
128
97
112
143
145
143
147
124
149
92
163
86
147
88
145
174
149
162
123
164
153
181
119
218
118
147
159
179
151
167
116
60
149
173
180
186
79
134
138
177
121
131
166
120
121
188
106
211
82
156
189
184
118
166
87
154
192
168
124
160
161
185
140
126
155
121
150
109
148
206
189
139
164
151
133
144
127
140
180
158
195
140
249
120
197
161
107
159
133
126
233
159
236
158
144
170
166
145
267
141
179
226
177
212
149
138
124
125
254
154
202
186
182
227
158
210
128
140
97
169
221
182
182
87
194
129
245
183
153
134
149
274
170
261
125
102
217
125
292
183
353
138
162
271
158
237
54
132
194
118
229
224
217
208
224
240
251
221
172
172
166
176
175
153
139
215
298
157
205
185
151
165
163
177
129
300
143
233
334
177
225
117
195
250
152
198
144
280
149
282
205
206
230
126
234
215
181
104
279
187
190
309
174
220
154
127
137
133
159
172
252
200
193
256
223
270
117
169
187
112
168
167
204
195
274
208
168
212
183
176
156
129
133
277
159
185
243
167
174
144
179
158
187
169
91
213
194
207
225
169
191
158
156
127
169
168
237
207
192
239
141
176
182
190
153
165
72
152
245
202
165
265
132
218
137
136
183
178
162
248
141
153
247
172
129
143
109
126
171
135
117
193
183
189
265
137
167
154
140
152
139
137
105
203
220
205
208
112
130
184
123
127
153
160
180
138
205
197
133
112
153
119
123
119
153
80
176
202
159
227
202
134
122
125
132
122
151
157
154
159
156
99
152
169
127
123
180
203
186
186
137
163
189
173
129
176
96
103
166
116
159
113
152
238
223
199
168
151
130
203
129
187
99
180
99
182
155
180
169
153
109
167
163
110
164
168
188
163
150
130
122
142
91
145
195
122
189
143
129
135
176
164
101
156
126
167
239
248
149
146
179
82
188
126
123
148
185
152
198
153
128
179
129
130
188
182
178
219
245
260
128
172
135
184
173
174
154
183
188
232
136
240
208
111
145
223
117
165
172
133
212
260
182
135
211
103
102
124
138
202
239
127
170
225
164
135
194
140
224
151
206
82
208
197
206
216
177
160
186
119
220
89
221
161
114
260
256
187
180
98
124
156
107
131
122
218
209
184
198
183
144
276
142
203
101
184
123
129
154
181
222
97
157
160
157
187
99
139
159
182
212
189
163
219
153
96
188
181
125
53
146
205
157
213
116
281
184
137
152
140
123
142
114
196
160
187
171
147
195
172
121
132
141
153
147
176
200
138
107
145
105
232
121
150
158
103
110
195
159
141
166
167
94
139
112
121
86
117
137
157
154
170
150
184
170
204
132
145
130
133
141
137
145
121
148
161
214
142
124
121
88
122
225
102
167
134
175
162
138
146
109
66
107
144
206
179
105
129
168
129
150
113
213
141
106
146
261
155
97
107
154
152
138
119
91
98
211
131
169
181
187
128
168
177
119
75
99
126
212
161
192
183
139
145
233
98
155
135
155
135
171
174
241
229
199
144
228
118
99
120
103
145
203
193
155
188
126
147
206
142
144
113
127
207
120
92
204
163
183
148
216
117
79
99
146
176
180
144
170
209
145
212
193
138
124
129
190
136
126
174
136
262
151
130
107
140
86
111
205
145
110
147
203
205
241
128
121
85
82
204
139
156
194
146
132
147
219
174
121
127
114
177
151
123
134
158
168
147
128
107
82
61
110
128
151
184
60
172
164
151
133
131
140
80
128
197
107
157
135
204
220
179
165
71
152
124
229
144
149
137
135
187
155
150
121
136
92
129
133
159
159
231
153
183
183
158
123
72
77
162
164
137
118
150
131
177
115
133
132
66
74
168
133
167
137
163
152
122
84
98
118
115
93
162
195
123
135
127
214
202
90
110
137
89
119
130
157
183
140
148
152
168
130
136
95
104
118
159
115
121
144
123
138
134
118
79
146
199
96
165
185
141
163
154
180
116
137
123
144
164
156
172
103
128
113
230
136
93
128
108
132
196
224
197
62
144
139
189
92
104
86
150
163
160
146
190
173
197
159
150
67
107
134
129
155
211
194
104
198
117
170
159
191
133
130
158
205
273
308
228
148
162
136
193
91
90
149
159
111
221
93
167
146
138
156
113
71
187
252
150
170
213
130
236
114
135
145
147
54
263
187
197
282
209
167
215
174
149
235
144
121
258
203
194
211
165
223
200
177
131
175
147
136
233
220
178
204
179
172
177
217
164
160
161
195
290
228
179
227
245
276
185
207
202
133
186
215
175
213
216
191
207
188
204
245
213
148
141
202
165
218
243
143
304
190
171
150
130
93
222
245
214
236
295
253
283
132
150
231
105
125
162
220
185
267
172
286
235
237
286
161
87
185
273
117
301
232
227
253
177
188
186
212
106
218
172
249
241
205
245
284
149
178
210
143
137
245
228
219
300
175
308
199
124
287
176
154
187
292
142
218
201
198
217
170
151
167
193
150
230
238
214
243
130
286
163
124
285
211
101
182
226
196
189
206
158
260
201
112
206
143
66
180
311
216
275
153
259
254
154
138
177
109
139
267
131
182
291
188
227
149
130
170
237
125
153
368
195
199
234
146
272
147
85
264
177
110
207
234
145
262
183
242
177
163
84
209
121
123
162
97
152
255
122
159
232
140
155
117
94
176
226
130
162
157
230
226
154
137
122
148
171
146
156
152
212
107
221
242
133
121
148
102
95
195
130
140
160
146
290
182
61
129
150
104
166
127
176
180
118
181
252
143
122
81
63
137
146
171
156
111
89
230
133
128
84
80
64
78
238
166
166
124
102
185
152
91
96
79
99
97
114
160
130
76
154
Cr 2p/43
images-of-Cr-dots.vms
2003
9
26
19
8
28
0
10
Casa Info Follows
0
0
0
0
   Lens Mode:Field of View 2: Small Spot   Resolution:Pass energy 80    Anode:Mono(Al (Mono))(300 W)
   Energy(eV): 910.490    Dwell(ms): 300000     Sweeps: 1        Acquisition Time(s): 19660800
   Acquired On :03/09/26 19:08:28   C/N :On

C:\Users\mfl\Documents\XPS\PCA-presentation\demodata CasaXPS\images-of-Cr-dots.vms
XPS
576.2
Mono(Al (Mono))
1486.69
300
1e+037
1e+037
221
221
1
1
128
1
128
128
1e+037
1e+037
FAT
80
1e+037
-4.913
0
1e+037
1e+037
1e+037
1e+037
Cr
2p
-1
1
Intensity
d
analogue
300
4
0
1e+037
1e+037
1e+037
1
MFP Exponent
d
0
176
164
274
169
156
201
322
145
263
267
222
278
127
97
312
178
152
186
152
109
180
222
156
153
142
235
253
123
252
152
150
115
220
168
144
173
175
246
177
132
167
160
116
141
172
171
151
135
188
183
130
157
136
250
97
174
195
173
184
149
226
172
135
219
177
98
142
150
156
130
205
148
215
168
160
218
158
172
191
246
136
162
140
224
220
183
162
202
113
153
190
153
160
130
154
281
235
201
186
171
137
155
235
136
134
127
137
235
222
120
220
179
103
209
169
84
118
107
203
277
157
138
206
88
146
209
149
146
138
93
202
257
190
147
165
165
147
204
135
219
104
184
265
112
102
113
105
135
102
274
87
172
73
223
215
123
140
150
142
157
131
191
171
137
78
226
235
139
108
140
180
133
105
136
225
103
111
184
212
196
124
122
115
168
123
122
185
82
189
169
156
109
122
184
131
160
145
134
179
106
188
157
175
117
108
114
195
186
116
209
128
194
164
178
179
159
117
82
125
120
165
126
86
145
113
126
133
112
103
123
157
168
122
88
111
200
169
167
119
121
125
155
186
162
163
98
152
145
152
92
85
101
104
173
133
89
233
125
204
134
165
176
134
154
192
143
200
267
92
185
136
119
133
152
137
77
138
133
172
134
56
125
122
153
158
172
120
122
136
156
164
172
128
169
161
171
118
128
97
127
149
217
168
162
181
154
181
126
120
126
123
163
139
98
171
161
151
130
224
196
104
127
220
144
226
124
196
146
199
163
96
191
153
117
207
141
157
159
146
238
196
178
173
149
156
138
196
171
142
121
129
275
274
178
175
98
137
181
154
190
123
147
158
295
199
172
167
137
108
202
197
121
155
174
173
195
199
245
138
149
229
124
192
172
175
164
181
241
190
185
131
110
173
155
236
144
213
221
260
168
229
201
136
221
163
131
159
165
98
160
253
156
169
147
229
229
190
180
131
235
162
265
339
212
248
101
182
262
153
133
188
212
185
222
238
230
187
143
175
153
176
182
283
140
186
400
175
228
147
147
132
166
139
150
160
132
196
217
205
222
141
187
197
75
133
146
207
145
280
195
167
206
109
143
134
121
136
203
188
179
290
177
175
186
131
165
149
184
134
264
193
286
323
133
181
116
125
117
147
169
144
213
195
275
166
174
142
162
142
140
101
149
184
174
210
221
110
166
130
102
173
214
121
164
234
158
154
204
192
133
160
157
142
145
141
199
207
189
261
191
135
145
143
139
202
157
126
165
180
166
280
160
135
130
64
201
161
113
159
139
169
178
180
134
103
169
138
129
166
175
139
113
135
200
211
215
169
108
126
152
117
125
155
190
247
130
108
126
130
87
127
206
158
198
197
182
154
158
102
110
111
128
146
144
167
138
174
102
114
188
113
98
124
124
152
194
142
115
190
178
119
126
153
106
136
138
121
166
187
154
126
147
150
169
152
129
192
171
142
144
189
195
133
117
199
125
132
122
156
180
182
251
162
171
179
129
187
82
121
107
275
227
179
175
134
139
112
165
134
186
160
219
149
170
156
141
184
118
153
192
141
172
214
285
157
209
198
131
149
125
132
241
150
130
245
260
193
131
220
187
91
184
112
193
177
181
156
191
192
147
199
126
180
131
198
131
180
204
128
231
190
172
139
130
207
117
255
261
175
145
232
197
166
161
152
165
97
139
114
210
172
232
196
176
109
179
118
212
144
134
135
154
236
219
179
209
145
171
144
164
96
156
148
141
199
159
162
158
221
131
178
100
175
120
127
112
171
170
137
277
234
101
244
167
127
203
119
106
197
138
174
191
240
143
145
109
122
153
138
110
181
184
202
109
118
194
180
186
107
92
127
159
112
205
172
173
198
214
124
107
105
159
183
149
146
148
170
162
136
200
95
92
105
140
118
174
161
159
126
153
147
143
95
146
102
102
159
144
127
140
233
144
213
115
99
174
138
134
218
155
162
141
174
186
143
112
89
125
102
79
255
150
66
177
206
142
106
147
101
144
127
156
158
136
141
98
173
138
150
157
114
117
179
134
148
148
201
184
147
122
134
110
139
134
154
214
173
170
124
157
127
149
134
99
103
156
164
175
123
156
183
127
164
106
122
122
164
231
141
128
149
118
165
145
109
110
119
172
141
227
204
152
171
136
171
192
163
147
104
83
179
182
150
164
173
225
166
156
166
85
117
144
212
155
171
108
156
143
225
128
111
86
89
184
135
149
140
148
153
171
248
151
123
100
86
164
227
177
156
144
155
216
225
127
97
119
134
132
134
214
91
162
114
186
118
139
118
95
174
179
143
145
225
181
162
207
190
63
84
141
162
142
126
119
190
193
142
128
106
93
69
118
189
119
140
164
221
159
221
97
95
97
72
140
203
143
165
132
201
171
166
126
93
112
49
208
136
169
112
124
219
110
112
106
134
70
117
111
180
89
149
173
108
180
112
103
141
92
156
175
226
132
132
166
155
146
82
130
89
93
187
156
142
140
187
120
210
173
187
97
115
146
135
220
204
161
164
184
204
122
100
99
175
176
179
194
156
154
178
233
124
124
108
88
186
174
163
180
90
182
174
157
115
100
119
134
146
134
215
191
151
130
138
135
105
150
102
130
169
242
196
155
233
136
146
141
124
133
178
299
143
191
243
218
138
135
137
134
105
153
191
147
234
268
170
188
191
147
156
164
84
116
167
202
204
291
113
159
154
148
189
216
106
232
265
154
207
191
212
233
205
160
182
122
100
187
174
152
275
175
194
130
191
191
144
118
116
149
169
330
185
132
238
166
183
198
166
141
207
327
148
270
218
158
232
162
215
191
125
140
231
209
270
189
141
292
204
164
246
267
83
170
213
127
221
265
121
308
139
147
165
166
157
156
243
218
250
187
311
226
157
156
239
81
172
195
179
286
266
129
187
206
161
247
148
117
180
314
184
267
218
289
303
156
179
209
209
132
242
235
263
288
160
225
213
170
156
188
91
198
331
254
218
232
123
286
184
178
176
101
157
225
267
202
320
225
226
184
185
159
206
151
127
223
293
163
259
145
197
249
151
216
161
63
159
171
152
291
244
153
235
214
139
214
127
104
290
225
223
307
165
325
223
141
100
221
124
113
256
173
195
211
173
214
187
103
177
142
115
189
283
202
232
181
137
185
204
169
229
146
137
234
231
173
242
158
184
253
141
129
176
111
147
188
171
135
251
139
253
218
127
183
170
88
197
214
187
186
180
263
223
117
112
132
91
99
192
180
165
214
100
178
198
165
127
110
79
122
174
127
196
198
145
237
173
128
132
95
85
148
186
150
131
150
172
287
96
136
110
87
109
180
187
194
147
106
222
145
132
88
152
111
111
160
123
176
146
108
131
120
114
84
118
65
117
114
160
123
86
90
Cr 2p/44
images-of-Cr-dots.vms
2003
9
26
19
8
28
0
10
Casa Info Follows
0
0
0
0
   Lens Mode:Field of View 2: Small Spot   Resolution:Pass energy 80    Anode:Mono(Al (Mono))(300 W)
   Energy(eV): 910.790    Dwell(ms): 300000     Sweeps: 1        Acquisition Time(s): 19660800
   Acquired On :03/09/26 19:08:28   C/N :On

C:\Users\mfl\Documents\XPS\PCA-presentation\demodata CasaXPS\images-of-Cr-dots.vms
XPS
575.9
Mono(Al (Mono))
1486.69
300
1e+037
1e+037
221
221
1
1
128
1
128
128
1e+037
1e+037
FAT
80
1e+037
-4.913
0
1e+037
1e+037
1e+037
1e+037
Cr
2p
-1
1
Intensity
d
analogue
300
4
0
1e+037
1e+037
1e+037
1
MFP Exponent
d
0
125
203
314
324
202
206
212
153
247
312
291
208
160
154
285
190
175
149
111
129
183
141
139
258
155
186
214
124
121
186
158
161
270
168
127
151
136
267
212
195
166
174
142
192
241
178
162
144
115
198
166
148
160
137
94
178
231
205
166
88
188
128
199
209
134
162
74
255
155
147
174
84
242
224
127
195
164
95
172
229
202
96
160
204
308
156
193
210
111
128
189
183
193
123
140
304
172
97
195
206
122
164
227
69
147
167
180
224
172
118
171
122
135
169
277
139
137
89
237
273
149
171
152
113
141
181
140
119
134
100
256
193
146
143
164
124
129
148
109
251
94
119
262
174
130
166
94
100
186
148
123
141
95
238
231
219
63
137
129
107
149
118
114
132
94
256
235
139
160
134
139
157
145
148
248
127
181
142
173
130
197
120
158
131
162
104
159
107
181
165
132
173
160
130
164
136
137
122
159
108
192
227
124
116
176
121
131
174
178
229
76
134
129
207
139
154
176
122
175
142
170
217
88
185
168
144
108
101
156
99
159
137
116
136
90
230
198
243
74
111
168
164
123
166
177
146
161
132
152
160
174
102
124
151
191
184
162
83
174
119
176
109
114
166
156
153
142
222
155
135
121
151
173
130
101
98
169
211
147
158
164
143
141
186
163
82
115
129
176
128
107
180
119
202
133
154
129
155
137
176
95
166
193
196
170
164
136
139
202
160
109
205
142
106
130
138
145
177
163
145
155
163
242
174
215
129
205
133
190
189
177
223
76
155
166
136
150
135
156
110
196
168
119
147
133
187
189
178
136
215
145
177
268
107
180
119
155
235
176
170
111
207
184
216
146
158
207
133
125
228
171
198
149
165
217
289
192
224
132
145
195
153
212
146
226
171
225
348
157
252
139
111
208
143
236
191
153
197
201
212
199
156
93
168
185
170
121
199
171
187
253
197
284
188
149
213
180
168
170
184
140
231
326
180
202
120
157
199
168
181
186
197
145
241
186
282
163
140
216
161
128
141
250
161
220
360
143
257
119
108
145
162
164
135
251
167
174
248
146
194
92
123
124
168
152
160
212
138
230
142
195
133
105
145
170
138
120
257
137
176
223
155
192
107
169
145
162
151
146
237
173
210
243
181
137
128
181
134
111
179
147
163
168
267
153
139
144
172
181
188
146
89
176
165
195
253
169
198
135
136
211
115
185
179
146
199
221
143
138
147
157
131
210
142
105
260
185
165
215
152
151
153
140
112
174
171
159
206
141
184
140
137
143
88
123
113
141
127
234
157
171
174
224
166
121
102
124
123
205
164
197
227
118
189
208
123
130
104
144
167
216
139
178
199
157
199
218
110
128
103
157
108
130
231
163
168
157
104
122
118
99
135
144
147
108
132
185
134
172
119
127
128
142
158
169
145
102
181
160
256
173
219
154
157
107
153
151
147
164
170
192
135
113
130
141
115
164
176
198
116
154
173
179
108
122
190
147
124
174
184
221
157
185
163
95
130
178
185
164
149
228
123
239
156
149
150
145
199
207
162
82
134
187
242
200
127
157
109
145
193
161
161
172
197
201
219
132
145
96
180
113
249
206
181
207
261
177
236
194
179
87
135
151
191
255
138
195
205
183
119
218
108
129
133
206
169
210
183
163
210
245
137
198
133
225
170
201
232
174
213
166
129
140
175
104
123
114
101
145
190
216
211
129
203
138
254
147
188
113
165
187
142
181
199
187
204
154
173
102
245
93
106
146
132
220
220
127
137
196
138
195
80
148
128
169
128
175
192
113
216
217
171
177
187
107
95
134
129
216
232
184
185
229
109
137
118
100
136
117
171
219
149
145
236
131
204
138
144
128
133
122
144
184
171
166
124
110
155
109
109
131
130
143
138
165
173
155
201
142
173
154
117
133
122
202
195
178
153
159
134
196
227
80
92
108
110
139
222
147
162
197
158
185
137
108
149
118
173
192
173
137
150
143
153
171
127
119
57
110
149
202
170
88
145
173
172
130
108
98
147
152
142
139
93
164
197
142
151
106
174
162
204
155
155
135
134
149
178
166
105
126
109
90
144
183
231
124
205
188
179
133
147
116
99
135
231
152
190
182
188
229
89
200
132
165
108
102
179
151
146
197
161
150
140
184
119
61
90
183
136
153
148
130
231
128
210
251
176
120
156
175
170
146
145
151
260
172
107
144
83
77
162
212
241
150
134
158
161
219
118
141
81
156
138
129
126
155
177
234
133
244
101
101
92
127
139
189
171
133
149
136
218
184
100
106
116
122
176
94
196
81
137
122
204
74
89
125
79
110
130
141
190
187
203
215
147
138
47
76
106
155
118
136
144
146
218
185
166
93
101
106
76
127
119
164
230
182
107
167
198
102
78
139
135
180
140
94
140
181
204
156
140
96
73
103
204
152
195
121
166
177
160
132
104
119
171
115
137
171
184
160
170
117
147
99
116
77
174
114
131
106
195
97
204
239
136
131
155
116
102
151
154
156
127
182
168
162
161
82
136
114
133
156
217
151
145
162
193
154
141
112
162
126
191
100
222
139
169
168
179
106
146
95
125
155
235
157
266
87
123
181
174
98
132
86
176
205
169
182
162
172
167
119
150
122
128
157
202
139
210
186
159
175
164
211
171
133
120
171
171
210
219
169
190
200
165
208
91
120
143
217
167
198
166
179
145
213
142
232
116
125
142
234
123
214
310
121
180
197
187
187
131
126
200
233
134
258
232
148
206
131
107
166
156
85
262
188
223
256
200
253
179
136
198
178
121
177
211
150
267
227
132
204
122
179
164
144
154
204
274
177
230
180
180
251
180
200
184
168
182
247
199
253
264
196
217
221
180
213
171
145
127
271
122
244
239
106
265
142
139
212
115
117
271
290
166
114
264
196
229
125
183
128
103
139
286
163
307
246
206
290
200
213
232
236
116
181
362
154
276
218
291
289
127
153
210
170
186
235
202
186
187
201
211
228
112
235
144
158
103
259
160
258
244
160
242
176
191
163
167
113
190
255
147
262
278
188
217
164
191
147
211
110
195
273
188
198
154
279
199
165
158
128
101
192
215
163
172
217
138
289
233
162
199
160
76
178
226
169
245
260
183
220
153
180
167
143
167
250
149
162
201
156
212
224
130
147
215
125
232
226
213
272
212
93
190
205
99
170
197
106
232
188
194
238
160
249
215
172
92
171
116
132
224
120
185
256
160
178
178
140
179
185
86
186
168
127
195
142
234
201
132
130
126
77
94
145
170
152
165
182
218
204
196
154
130
99
108
203
209
179
186
166
205
223
138
101
150
80
185
193
204
117
80
203
223
158
177
103
120
106
132
191
134
170
102
235
180
133
108
149
167
86
183
91
167
127
154
219
87
126
92
148
161
123
143
109
137
77
75
Cr 2p/45
images-of-Cr-dots.vms
2003
9
26
19
8
28
0
10
Casa Info Follows
0
0
0
0
   Lens Mode:Field of View 2: Small Spot   Resolution:Pass energy 80    Anode:Mono(Al (Mono))(300 W)
   Energy(eV): 911.090    Dwell(ms): 300000     Sweeps: 1        Acquisition Time(s): 19660800
   Acquired On :03/09/26 19:08:28   C/N :On

C:\Users\mfl\Documents\XPS\PCA-presentation\demodata CasaXPS\images-of-Cr-dots.vms
XPS
575.6
Mono(Al (Mono))
1486.69
300
1e+037
1e+037
221
221
1
1
128
1
128
128
1e+037
1e+037
FAT
80
1e+037
-4.913
0
1e+037
1e+037
1e+037
1e+037
Cr
2p
-1
1
Intensity
d
analogue
300
4
0
1e+037
1e+037
1e+037
1
MFP Exponent
d
0
229
192
274
230
152
190
197
97
186
201
260
286
191
212
296
157
177
168
144
188
133
213
147
166
125
158
246
207
173
85
135
182
264
146
156
259
194
244
151
230
147
179
117
187
247
172
148
121
177
231
147
164
149
187
122
210
229
132
207
199
190
220
168
227
147
149
108
178
232
134
184
160
202
190
248
175
133
152
208
174
120
92
125
195
221
214
188
149
154
133
155
219
142
114
133
232
167
142
210
161
132
111
305
211
110
160
126
256
211
171
158
184
131
185
211
139
141
72
196
259
180
115
188
115
124
266
193
200
114
127
231
249
125
184
135
96
105
175
79
259
86
149
257
193
114
173
143
109
228
184
170
187
157
146
261
167
135
186
85
86
174
172
153
110
107
226
211
188
165
122
117
148
168
100
243
157
171
171
177
115
160
78
121
151
118
187
160
95
169
225
212
102
149
101
107
154
174
189
117
112
219
230
173
134
94
155
190
193
148
192
137
126
136
174
111
159
90
168
151
140
111
167
108
243
171
156
186
165
164
153
186
204
105
186
126
120
226
156
111
121
148
202
158
172
139
116
183
183
193
146
215
155
127
220
188
136
204
61
185
225
121
189
160
132
158
174
132
208
95
113
160
196
120
147
174
142
176
165
137
160
114
130
165
246
162
147
198
191
177
199
115
139
96
205
121
185
133
172
130
184
147
196
150
207
237
145
175
218
130
201
111
147
128
80
196
185
183
187
232
252
127
140
173
147
272
102
150
149
162
172
118
183
159
124
220
162
177
157
171
203
222
238
174
147
140
163
202
219
119
136
155
152
255
169
186
114
146
174
210
196
133
222
144
254
165
214
215
149
206
300
157
161
118
155
172
284
187
244
139
109
235
189
226
204
199
165
218
262
221
196
96
180
185
164
195
209
216
155
250
188
194
244
109
238
190
170
151
198
190
183
222
161
262
133
170
162
152
129
148
226
206
309
340
137
208
177
100
263
192
203
202
203
135
327
223
247
207
111
154
151
163
183
273
131
235
236
210
217
155
180
127
164
210
185
232
150
249
322
147
234
85
156
227
114
173
167
205
151
237
179
175
206
121
169
161
203
182
282
181
209
268
152
132
172
118
133
167
191
107
299
182
266
261
167
164
98
175
187
221
188
219
203
157
279
204
176
126
156
199
104
157
126
189
152
158
202
118
216
134
76
216
151
84
207
169
145
272
263
173
107
118
126
117
152
192
215
183
192
193
170
105
204
162
114
173
163
129
179
190
207
194
172
115
162
151
106
169
148
175
212
183
227
188
199
102
106
149
179
147
107
118
181
219
177
171
85
146
86
96
120
141
116
162
202
240
135
154
148
168
134
194
154
141
149
235
190
154
153
159
156
144
138
152
149
152
164
176
196
180
138
158
151
158
213
113
223
170
219
158
218
145
166
222
86
122
158
208
105
171
161
163
172
149
137
139
123
150
165
188
128
141
150
119
85
134
107
116
147
183
186
238
200
158
167
121
91
225
146
181
163
185
132
196
151
129
89
145
129
167
147
186
187
234
170
139
140
152
138
86
220
129
133
245
236
170
220
198
97
114
232
120
271
157
179
166
283
167
214
172
172
146
76
132
186
213
196
192
198
189
133
178
136
225
123
213
160
184
204
241
247
149
201
234
119
223
91
229
199
169
219
236
185
150
169
230
122
139
117
186
198
143
214
211
227
146
204
164
238
165
144
104
129
225
138
124
181
160
221
171
253
121
159
187
166
164
238
154
141
206
123
230
149
115
168
135
136
159
186
180
243
320
184
218
166
116
127
143
137
198
121
209
194
152
142
311
176
171
127
169
172
215
121
151
222
156
157
171
149
87
156
140
157
195
224
150
205
139
248
104
141
113
159
160
172
211
163
184
190
109
161
132
85
71
103
188
129
98
174
170
174
149
181
153
149
116
100
159
140
178
138
233
153
164
145
150
116
147
163
147
131
193
156
177
174
150
127
132
108
136
173
171
111
120
135
167
182
120
195
130
117
174
190
115
117
144
205
177
164
145
126
73
191
159
115
140
130
177
167
226
114
122
84
71
139
168
184
187
178
167
130
129
136
173
91
132
217
164
131
162
161
182
152
188
149
161
142
176
193
150
177
176
160
175
145
130
145
133
135
164
180
119
238
164
181
157
247
194
159
67
159
192
185
145
167
157
213
177
164
148
150
119
165
142
201
133
184
238
152
185
122
96
73
115
196
156
159
179
187
154
183
185
161
134
83
101
135
180
148
190
176
185
169
156
104
104
119
159
177
132
186
79
164
121
214
144
120
114
76
202
128
169
216
162
144
168
193
129
93
96
121
133
125
142
102
236
168
193
158
136
63
80
128
161
124
184
246
133
128
168
125
122
64
128
220
140
142
132
171
145
157
137
169
141
114
101
196
102
130
138
154
157
200
91
66
123
145
90
175
149
93
242
237
156
164
118
130
161
98
143
154
134
171
153
191
158
164
118
103
118
182
240
134
151
133
143
133
145
176
99
122
149
250
184
179
161
172
178
177
143
202
79
117
153
135
166
197
157
122
170
152
115
94
111
90
215
206
171
197
132
197
185
169
171
159
68
168
174
187
206
202
154
116
168
130
162
142
143
153
146
269
242
144
191
150
146
154
130
108
146
221
205
252
223
172
147
159
134
107
165
122
222
149
241
205
211
197
188
144
173
118
115
141
196
135
231
283
125
164
130
211
154
170
115
170
303
129
320
183
252
308
172
169
203
87
113
229
253
194
262
199
189
167
112
229
127
146
155
214
126
181
155
180
248
209
154
169
144
128
227
244
144
216
221
272
314
117
176
222
147
149
142
192
273
229
135
324
158
175
268
144
149
177
265
152
300
286
137
269
176
202
228
154
146
175
301
157
215
147
189
254
157
258
210
83
122
289
155
330
308
146
196
244
168
221
205
112
164
284
212
279
256
308
213
158
158
265
184
116
193
242
219
246
220
287
232
154
207
147
127
176
260
227
207
229
152
301
203
161
199
213
128
148
210
179
270
215
156
189
166
163
194
200
119
195
271
140
233
215
292
261
153
148
159
121
199
249
222
190
257
189
283
223
149
231
221
82
207
243
158
215
223
244
160
195
113
159
132
112
185
207
215
235
167
235
227
152
213
186
136
164
202
155
228
220
158
251
202
103
222
106
113
217
239
180
299
239
260
206
158
112
151
117
153
174
165
196
203
152
158
240
132
139
217
98
199
200
184
153
222
215
280
176
119
163
79
203
187
178
212
158
140
200
199
151
124
160
104
163
210
164
187
164
105
223
136
103
142
129
71
173
166
168
136
113
173
195
143
108
94
124
85
121
205
177
175
114
267
223
143
83
99
74
109
172
206
169
194
85
178
137
147
88
114
72
121
147
107
122
96
82
Cr 2p/46
images-of-Cr-dots.vms
2003
9
26
19
8
28
0
10
Casa Info Follows
0
0
0
0
   Lens Mode:Field of View 2: Small Spot   Resolution:Pass energy 80    Anode:Mono(Al (Mono))(300 W)
   Energy(eV): 911.390    Dwell(ms): 300000     Sweeps: 1        Acquisition Time(s): 19660800
   Acquired On :03/09/26 19:08:28   C/N :On

C:\Users\mfl\Documents\XPS\PCA-presentation\demodata CasaXPS\images-of-Cr-dots.vms
XPS
575.3
Mono(Al (Mono))
1486.69
300
1e+037
1e+037
221
221
1
1
128
1
128
128
1e+037
1e+037
FAT
80
1e+037
-4.913
0
1e+037
1e+037
1e+037
1e+037
Cr
2p
-1
1
Intensity
d
analogue
300
4
0
1e+037
1e+037
1e+037
1
MFP Exponent
d
0
253
175
296
275
251
258
184
162
201
267
242
306
182
191
263
147
168
176
206
154
105
144
136
223
157
274
150
195
198
183
118
131
242
156
169
216
157
226
165
173
182
129
127
135
177
[...]
95
116
82
96
87
92
57
175
115
101
108
72
47
36
46
77
125
98
93
166
212
130
95
88
81
54
113
101
85
141
141
122
181
82
83
70
114
156
171
155
101
231
213
144
208
118
69
75
101
86
120
164
130
100
201
132
57
180
73
132
65
121
143
100
140
173
96
125
104
178
72
138
82
152
168
124
164
215
120
110
127
118
97
95
101
81
143
168
71
105
97
67
330
107
207
136
80
67
109
104
122
58
102
93
157
62
103
109
142
97
80
138
68
91
57
156
106
72
55
48
66
91
78
70
76
87
209
252
61
122
65
78
60
29
80
78
127
95
108
178
59
83
48
55
36
61
41
63
66
91
127
82
99
71
31
86
72
69
71
114
106
108
108
98
95
60
51
52
43
87
65
90
55
28
68
43
99
32
56
85
45
72
113
57
53
61
91
58
59
42
67
64
40
120
119
65
40
122
66
127
78
53
71
100
70
88
56
41
32
127
68
107
50
79
53
16
75
92
90
61
58
79
91
87
68
41
65
74
71
102
67
88
57
120
77
117
70
88
56
46
86
68
57
66
93
74
82
95
67
94
114
108
77
95
165
112
57
85
98
84
74
45
157
110
61
83
73
138
82
124
179
63
71
108
62
94
62
102
75
128
124
75
72
58
96
78
128
98
66
76
69
70
253
141
111
67
74
93
68
60
82
81
125
84
117
90
53
56
60
73
89
68
55
90
97
135
123
51
40
38
104
52
110
84
137
63
42
171
92
58
54
87
81
75
61
58
75
97
105
50
65
35
10
83
98
77
89
43
53
62
162
74
32
51
52
74
74
70
43
71
57
56
102
93
55
96
55
57
87
73
27
60
93
58
53
44
94
70
69
75
47
48
97
74
50
34
73
67
41
31
60
89
99
79
84
65
106
83
49
46
48
44
78
51
49
48
104
53
97
53
46
64
66
42
59
81
94
60
89
77
93
52
48
51
53
59
48
126
55
78
37
95
42
44
62
25
64
84
78
64
58
99
52
74
94
26
54
108
77
48
175
108
58
85
76
85
93
59
95
91
52
83
144
75
74
85
107
67
58
44
59
77
91
156
162
30
76
54
69
59
51
74
84
44
66
172
92
76
74
62
101
61
71
95
117
89
221
187
42
87
56
77
67
85
51
86
110
102
157
219
134
110
52
96
131
62
56
142
37
104
218
163
101
80
67
107
107
75
114
175
32
227
198
71
138
54
103
144
111
61
165
164
65
283
284
95
102
58
53
235
56
89
184
64
232
282
170
194
134
90
159
137
60
136
241
114
239
180
117
199
93
103
181
99
63
254
226
127
261
229
203
275
93
159
213
65
102
168
128
229
231
204
263
161
57
102
127
69
204
229
62
252
253
65
298
87
93
212
163
70
196
258
160
262
234
185
216
73
155
217
88
148
247
44
233
268
202
295
167
107
211
184
46
137
343
125
229
276
242
330
73
91
209
156
67
197
172
162
249
205
306
166
97
159
173
79
153
231
83
211
215
123
273
123
93
243
140
96
184
216
126
223
167
269
198
57
171
172
143
85
203
173
167
274
198
255
178
79
243
190
51
177
262
91
244
211
95
208
156
49
225
137
42
259
157
99
281
210
322
293
101
124
177
74
97
269
65
159
302
182
289
207
61
211
214
65
134
290
86
204
218
55
243
163
41
186
137
51
216
75
85
250
134
198
152
78
101
192
25
79
227
82
78
207
77
201
213
65
194
160
54
139
127
103
183
108
280
258
85
65
141
28
45
121
67
78
151
103
210
211
100
77
90
73
91
124
72
88
93
44
260
134
42
85
78
40
57
92
95
99
65
164
224
55
22
56
80
45
62
90
71
114
95
273
106
90
75
70
47
56
93
77
119
106
42
202
77
58
70
40
38
51
72
71
115
82
34
Cr 2p/75
images-of-Cr-dots.vms
2003
9
26
19
8
28
0
10
Casa Info Follows
0
0
0
0
   Lens Mode:Field of View 2: Small Spot   Resolution:Pass energy 80    Anode:Mono(Al (Mono))(300 W)
   Energy(eV): 920.090    Dwell(ms): 300000     Sweeps: 1        Acquisition Time(s): 19660800
   Acquired On :03/09/26 19:08:28   C/N :On

C:\Users\mfl\Documents\XPS\PCA-presentation\demodata CasaXPS\images-of-Cr-dots.vms
XPS
566.6
Mono(Al (Mono))
1486.69
300
1e+037
1e+037
221
221
1
1
128
1
128
128
1e+037
1e+037
FAT
80
1e+037
-4.913
0
1e+037
1e+037
1e+037
1e+037
Cr
2p
-1
1
Intensity
d
analogue
300
4
0
1e+037
1e+037
1e+037
1
MFP Exponent
d
0
151
127
298
131
98
165
227
95
203
221
211
261
56
91
269
93
130
163
130
97
154
179
102
168
59
222
196
114
150
134
103
95
217
180
91
191
58
238
268
116
171
183
58
182
242
152
224
76
123
194
95
178
108
130
71
193
198
101
222
65
229
125
51
182
167
71
100
243
194
73
124
77
226
184
81
198
161
57
88
232
63
121
54
188
222
116
155
166
96
89
203
162
63
150
92
245
194
96
185
222
66
89
146
59
64
116
44
322
123
91
213
165
58
132
202
82
141
56
182
221
82
148
178
40
98
220
131
20
83
33
265
166
67
221
157
37
98
128
70
222
59
87
271
62
95
181
88
51
76
82
113
157
16
163
221
79
94
120
68
44
126
46
69
69
78
178
86
68
132
63
73
69
97
75
181
53
39
183
98
59
104
65
106
74
72
51
178
68
108
65
76
100
115
70
62
41
63
56
77
59
87
50
92
34
58
79
33
38
73
197
55
73
115
99
79
61
54
65
94
55
65
116
58
53
39
87
72
55
46
39
58
49
62
77
68
71
96
55
55
60
66
57
80
75
168
59
66
62
81
32
34
68
73
102
44
51
43
78
107
88
73
34
60
40
48
52
82
120
110
53
82
119
30
69
73
38
40
76
113
51
63
110
52
78
53
63
42
93
48
92
47
84
47
96
56
92
63
58
52
119
85
145
70
88
100
121
81
112
77
35
110
119
141
98
55
61
136
121
62
94
78
51
185
59
188
46
125
58
172
62
116
144
41
100
204
79
172
62
90
95
155
93
164
104
38
114
122
143
96
74
68
198
249
121
207
87
94
180
65
212
89
99
99
193
150
150
213
72
182
147
117
167
103
103
133
290
63
208
86
83
157
90
246
128
180
105
280
214
105
204
50
103
170
71
233
89
98
90
181
151
195
160
58
230
122
122
117
116
83
179
280
93
217
76
85
197
72
120
60
173
66
197
285
103
203
63
110
184
49
151
85
116
84
224
122
225
179
71
137
128
103
74
188
82
174
303
162
274
97
75
197
94
53
63
258
112
187
246
181
235
62
84
124
53
156
104
214
101
317
94
218
90
86
145
60
76
80
184
123
184
268
68
244
32
52
72
90
90
39
199
101
289
105
119
94
59
87
55
66
121
73
54
94
290
49
139
93
45
63
79
43
76
150
69
130
136
43
129
71
35
49
78
64
98
105
79
208
56
91
83
37
56
73
88
64
58
89
83
169
126
83
47
52
56
121
55
70
127
74
55
136
101
98
93
54
77
77
88
52
88
66
107
76
67
31
26
69
59
33
105
103
66
74
112
92
57
84
55
64
128
34
92
67
83
88
100
100
82
72
76
82
69
77
84
76
52
87
49
57
27
79
56
72
88
60
88
96
66
77
62
42
25
85
111
112
130
40
59
82
101
87
61
88
67
41
118
98
83
78
84
42
77
46
48
78
123
88
103
130
55
129
95
70
69
80
52
100
65
111
75
211
133
82
95
58
56
77
63
84
69
171
138
162
120
61
61
46
49
89
99
113
72
156
123
98
47
145
100
70
103
96
45
146
180
94
189
87
87
74
146
93
193
151
63
157
257
135
83
51
70
81
98
96
140
236
143
80
198
193
69
198
43
137
116
135
64
193
204
154
129
128
90
199
66
144
86
213
131
151
166
203
123
116
149
100
62
76
75
135
172
184
142
125
188
62
183
67
193
109
105
82
89
169
137
72
120
119
179
95
156
53
97
127
47
180
96
112
73
161
104
57
45
86
84
82
82
104
122
62
210
263
58
128
70
75
64
33
70
88
89
107
98
177
87
108
44
73
65
81
69
115
73
123
68
60
115
91
45
31
53
39
89
47
77
100
147
74
54
41
68
46
31
87
124
83
68
51
103
85
65
53
49
47
35
100
132
48
74
56
80
89
52
57
53
61
53
75
76
73
57
66
56
78
77
68
35
80
94
78
83
63
71
75
38
47
82
57
34
84
79
69
74
70
72
103
109
85
76
50
32
82
96
74
39
112
56
51
87
99
105
74
51
81
122
92
72
58
103
102
91
57
74
65
118
89
99
77
79
62
71
99
100
107
86
42
145
111
78
43
70
79
61
123
113
63
94
79
122
95
85
75
63
63
91
106
75
94
77
99
125
78
98
84
69
106
197
147
129
56
78
148
71
82
45
55
77
78
110
77
79
107
55
61
91
61
63
109
114
148
99
72
79
90
112
81
87
94
84
105
77
175
55
67
49
57
88
79
55
86
77
75
64
160
30
76
71
53
92
61
80
55
101
107
133
64
94
50
24
41
114
54
55
90
98
31
100
112
35
29
54
73
84
41
37
91
62
68
39
35
48
44
66
92
29
108
83
79
71
109
75
71
54
51
69
57
110
86
78
73
78
70
73
42
49
83
67
84
65
40
73
68
51
52
32
49
38
48
38
85
26
64
81
48
96
74
43
54
70
89
87
68
66
62
50
79
109
66
64
53
77
65
94
116
77
138
40
99
80
58
20
75
81
30
130
95
97
83
73
97
45
84
37
79
58
55
176
97
57
99
106
83
36
74
78
92
71
170
143
54
75
87
113
113
31
48
84
110
93
204
151
69
79
93
77
73
87
59
143
76
136
205
63
68
84
82
104
55
63
118
175
127
228
213
47
45
114
87
102
25
65
268
80
109
165
109
96
69
54
100
68
70
143
145
90
203
222
118
123
95
92
146
65
52
167
238
114
282
190
122
114
65
57
134
67
134
160
87
175
183
150
177
155
83
115
153
46
192
203
91
229
166
87
204
92
98
154
116
50
285
237
80
300
201
269
252
88
167
252
64
135
206
119
240
224
216
239
98
68
206
224
67
161
276
67
324
205
131
204
56
128
200
120
80
158
276
164
243
230
262
297
101
156
240
59
140
217
109
197
185
143
263
242
71
216
184
36
144
316
52
240
238
333
179
109
103
171
167
76
305
148
126
266
201
215
236
113
201
212
72
112
261
76
226
228
132
289
248
87
251
187
58
150
228
85
269
213
217
216
88
132
202
148
106
239
132
152
231
190
252
169
69
266
205
77
142
283
58
278
222
148
242
157
82
303
147
40
260
225
111
344
192
263
207
85
138
182
106
75
219
73
128
246
117
256
218
64
127
251
66
116
229
107
235
209
67
212
135
62
247
114
27
202
179
104
199
128
192
195
72
101
151
48
124
232
91
68
167
79
236
204
81
113
150
35
96
121
95
124
130
249
192
50
62
133
78
52
119
99
90
186
49
244
186
62
75
118
69
35
126
85
98
95
48
260
143
59
58
71
42
48
76
66
85
70
196
175
56
73
77
84
49
81
120
58
74
80
224
140
74
35
51
50
33
105
55
39
50
72
126
88
38
19
44
60
52
72
45
73
55
32
Cr 2p/76
images-of-Cr-dots.vms
2003
9
26
19
8
28
0
10
Casa Info Follows
0
0
0
0
   Lens Mode:Field of View 2: Small Spot   Resolution:Pass energy 80    Anode:Mono(Al (Mono))(300 W)
   Energy(eV): 920.390    Dwell(ms): 300000     Sweeps: 1        Acquisition Time(s): 19660800
   Acquired On :03/09/26 19:08:28   C/N :On

C:\Users\mfl\Documents\XPS\PCA-presentation\demodata CasaXPS\images-of-Cr-dots.vms
XPS
566.3
Mono(Al (Mono))
1486.69
300
1e+037
1e+037
221
221
1
1
128
1
128
128
1e+037
1e+037
FAT
80
1e+037
-4.913
0
1e+037
1e+037
1e+037
1e+037
Cr
2p
-1
1
Intensity
d
analogue
300
4
0
1e+037
1e+037
1e+037
1
MFP Exponent
d
0
139
105
251
251
96
227
188
169
172
289
150
176
66
89
290
78
251
186
165
96
154
238
87
236
54
184
224
57
145
165
63
98
207
172
91
174
100
217
159
109
126
107
66
171
251
116
171
122
133
219
113
224
216
129
65
206
245
45
165
94
259
168
71
259
182
83
115
222
153
84
197
72
232
154
109
177
130
73
149
231
107
156
67
177
197
103
178
212
103
37
183
174
44
133
61
235
157
77
183
241
76
111
197
83
71
96
66
252
149
90
118
129
52
87
147
79
108
54
181
254
96
143
156
99
73
225
106
96
96
62
265
122
65
121
154
25
73
180
66
205
66
114
318
109
61
160
43
35
63
108
56
126
27
153
237
80
74
191
64
53
118
62
56
132
31
166
138
38
135
77
34
48
70
51
251
71
83
137
61
61
134
104
69
80
58
87
164
84
99
123
52
74
74
61
68
65
95
60
106
53
133
81
91
58
72
78
62
50
35
128
57
63
107
50
51
76
55
77
76
100
54
100
49
121
61
44
66
38
43
64
70
78
30
73
51
71
131
62
33
94
77
47
69
71
101
75
60
49
57
73
37
56
69
77
46
51
49
51
70
57
72
49
66
37
51
88
73
179
83
78
68
58
103
80
106
74
94
83
84
48
51
73
73
53
71
107
66
80
41
138
64
63
24
68
42
99
75
27
84
104
68
107
64
86
72
127
61
93
61
53
130
45
98
91
83
105
58
115
75
111
79
75
154
73
228
37
45
27
93
91
96
119
78
155
157
91
112
81
75
38
215
80
152
103
73
233
70
172
115
92
77
156
239
126
195
63
92
221
103
203
69
142
64
225
161
144
133
72
180
179
149
145
124
83
120
264
101
288
101
80
191
87
207
102
106
97
233
284
109
174
32
99
152
84
171
88
146
69
288
165
158
194
48
210
111
60
105
148
83
179
258
59
259
107
50
159
105
145
115
291
92
252
339
101
235
46
106
238
92
130
117
196
110
303
139
267
215
63
136
83
65
113
285
105
184
313
80
252
108
51
135
98
82
48
222
65
217
205
122
193
46
99
92
42
71
117
167
113
249
87
248
126
89
78
76
95
78
187
82
160
259
80
189
60
90
85
70
65
65
222
84
282
135
91
148
48
72
78
73
59
87
82
76
233
93
96
87
65
67
64
66
79
126
114
93
184
77
116
41
72
44
74
58
86
76
91
233
85
100
85
43
69
74
73
72
137
61
79
201
104
37
69
75
43
73
88
39
78
80
77
118
57
44
42
35
72
63
29
110
93
62
135
77
56
49
58
61
66
50
58
52
105
72
95
40
81
39
34
53
53
69
62
38
73
59
78
57
65
27
85
96
63
62
72
71
63
60
106
75
56
66
101
84
109
98
47
83
64
91
92
68
58
65
73
88
129
61
111
85
90
81
61
57
43
62
96
86
163
81
97
67
55
72
66
71
63
69
158
122
91
48
94
82
31
113
56
58
97
91
98
160
95
134
72
106
85
99
84
94
47
177
97
180
116
89
64
103
70
141
49
101
75
214
133
86
42
104
73
70
81
115
117
210
133
94
176
66
90
80
147
100
162
194
101
171
209
125
134
72
62
67
120
103
179
227
150
99
109
174
69
236
91
97
105
148
87
140
179
165
90
176
113
213
49
161
99
249
130
99
146
162
97
122
93
95
53
117
64
101
167
181
128
158
128
60
304
65
185
86
95
70
120
142
75
91
111
75
156
27
145
54
98
95
87
99
164
33
77
120
112
92
56
44
64
72
76
98
92
34
217
322
46
128
78
60
90
88
108
94
57
60
152
143
52
80
65
64
40
36
95
96
51
82
97
66
76
45
40
87
89
107
71
140
57
84
124
83
132
68
70
98
42
66
59
71
86
74
81
46
123
46
50
79
46
83
47
80
63
81
72
81
80
57
110
66
63
90
26
69
74
100
73
66
83
75
34
41
104
60
62
85
117
87
54
68
65
65
72
62
87
90
46
61
94
108
81
35
89
51
92
88
95
63
30
60
77
56
54
68
62
44
65
84
104
77
46
80
65
98
91
66
78
65
55
114
70
72
88
75
56
86
94
78
34
87
109
72
114
54
101
88
69
119
138
87
54
90
90
102
67
81
49
129
56
87
58
63
134
77
70
118
106
63
143
70
207
139
92
30
31
99
86
80
62
78
88
49
141
62
19
49
60
73
78
58
52
107
127
137
68
53
41
82
94
65
105
66
92
86
64
188
60
80
38
56
60
75
86
14
74
44
112
94
39
45
51
47
66
98
124
63
126
86
123
96
62
34
34
99
63
67
102
77
67
87
75
81
40
31
27
46
72
76
69
70
83
58
59
54
46
46
81
70
48
82
97
71
53
108
63
94
46
100
97
54
79
81
79
104
89
51
52
69
44
54
127
102
70
76
50
57
61
52
48
42
48
114
62
59
66
64
115
63
63
96
35
62
39
92
59
100
20
48
87
106
78
68
46
57
69
65
53
77
57
90
82
60
65
24
65
69
86
86
138
85
62
56
60
56
51
22
48
90
57
71
112
77
123
63
86
51
50
39
73
96
74
102
205
44
92
87
85
60
58
48
150
120
92
150
106
90
134
54
71
44
57
70
145
94
199
176
51
81
52
94
82
39
59
115
184
81
239
198
118
65
67
74
101
45
65
184
47
112
228
119
86
62
63
71
74
55
64
223
78
196
260
82
155
55
76
153
127
46
204
214
100
251
231
108
247
84
93
203
94
40
173
93
224
318
174
207
130
55
193
193
46
177
254
65
276
255
61
203
97
48
227
129
86
161
244
131
292
233
266
227
86
185
205
78
138
195
131
191
238
116
295
149
108
208
163
47
208
210
55
283
192
101
238
53
96
249
133
97
217
298
176
228
187
253
211
69
184
167
51
128
282
73
211
248
165
245
134
105
275
115
47
183
287
60
250
194
269
269
85
81
224
153
85
279
217
176
244
109
234
221
106
193
165
57
103
287
123
196
256
204
240
192
105
239
170
68
189
275
98
236
229
276
160
84
135
200
129
73
225
75
159
268
157
187
223
64
215
110
51
145
262
92
267
231
84
210
169
34
253
133
54
183
256
135
205
142
263
213
73
85
258
86
94
231
118
110
237
109
259
233
70
169
215
45
113
235
143
182
178
86
263
162
62
171
126
25
174
154
91
232
132
165
190
54
104
146
48
39
161
69
135
164
96
196
180
48
99
223
50
105
204
46
188
144
231
209
42
62
194
41
37
170
99
73
120
98
180
216
65
85
91
48
66
123
60
106
157
81
214
106
46
117
72
36
119
114
66
90
62
247
150
78
61
43
64
33
65
114
73
97
90
230
134
36
71
58
44
46
124
67
99
95
89
230
98
36
54
46
9
43
58
67
93
64
28
Cr 2p/77
images-of-Cr-dots.vms
2003
9
26
19
8
28
0
10
Casa Info Follows
0
0
0
0
   Lens Mode:Field of View 2: Small Spot   Resolution:Pass energy 80    Anode:Mono(Al (Mono))(300 W)
   Energy(eV): 920.690    Dwell(ms): 300000     Sweeps: 1        Acquisition Time(s): 19660800
   Acquired On :03/09/26 19:08:28   C/N :On

C:\Users\mfl\Documents\XPS\PCA-presentation\demodata CasaXPS\images-of-Cr-dots.vms
XPS
566
Mono(Al (Mono))
1486.69
300
1e+037
1e+037
221
221
1
1
128
1
128
128
1e+037
1e+037
FAT
80
1e+037
-4.913
0
1e+037
1e+037
1e+037
1e+037
Cr
2p
-1
1
Intensity
d
analogue
300
4
0
1e+037
1e+037
1e+037
1
MFP Exponent
d
0
132
91
257
194
66
202
275
155
197
266
189
260
100
59
240
71
191
173
176
59
219
211
106
183
113
226
209
82
147
143
123
89
235
172
72
140
92
233
110
112
191
187
68
155
214
115
186
55
170
232
78
142
128
97
81
257
203
64
192
62
234
177
80
209
181
59
88
202
152
72
86
91
280
177
105
251
162
74
186
204
111
176
60
166
237
86
205
182
80
71
207
171
97
136
60
272
144
60
181
154
62
81
160
138
42
107
70
207
185
83
190
143
52
121
125
95
127
69
166
185
46
105
181
88
52
175
142
55
139
44
215
191
116
196
110
87
72
146
36
258
61
88
218
69
91
147
98
49
134
126
77
193
27
176
150
72
86
156
50
87
152
94
42
95
35
254
133
84
115
136
54
79
94
51
207
72
71
160
89
82
76
29
40
65
69
110
164
53
145
82
121
65
70
58
59
85
86
51
117
37
98
61
86
84
44
40
51
83
41
215
38
52
94
70
67
55
53
90
75
55
78
85
42
79
49
68
53
36
74
56
56
82
50
120
71
76
84
83
81
60
58
74
60
50
123
52
71
85
53
51
92
67
76
93
49
30
87
62
96
47
62
61
49
93
62
98
48
89
42
69
57
78
74
90
59
46
82
38
74
81
44
113
41
92
65
42
61
111
99
142
69
123
32
122
105
84
73
48
60
123
74
109
77
48
55
97
100
97
83
75
59
78
119
117
56
59
111
67
67
129
50
77
193
54
200
33
50
53
151
124
133
105
44
120
113
101
185
47
45
107
188
113
144
81
60
119
60
144
105
108
66
192
195
89
174
50
90
213
57
231
92
87
46
218
89
159
154
51
163
161
110
175
96
98
104
333
71
230
149
70
221
100
178
78
147
65
170
279
89
220
104
76
180
50
168
67
151
95
275
121
241
154
63
196
143
78
91
133
62
239
293
82
180
82
63
168
69
111
149
181
79
194
283
158
217
66
159
171
57
90
107
152
74
313
145
223
172
54
269
80
70
49
277
120
203
272
66
187
103
70
162
79
66
135
252
96
189
192
208
230
82
53
81
53
47
88
212
89
231
97
137
123
57
81
80
52
55
170
104
156
307
97
188
43
76
96
89
55
42
176
109
252
174
110
114
57
80
90
54
60
106
122
128
297
58
90
119
93
84
37
90
62
173
55
162
224
60
118
93
97
73
93
97
120
93
104
159
114
102
57
37
79
60
59
79
84
103
99
183
76
26
72
48
81
40
35
65
52
90
98
96
24
38
40
54
34
49
47
97
79
84
87
81
82
110
37
98
51
100
47
82
105
64
100
59
84
56
84
87
82
73
58
51
106
56
60
106
82
62
83
75
106
93
81
53
60
102
63
56
73
46
101
91
123
76
106
86
87
59
62
84
82
26
64
81
111
72
114
117
105
66
86
67
110
74
82
135
77
108
49
68
53
83
27
70
52
105
165
135
72
99
112
78
63
74
101
86
69
110
91
169
97
51
89
42
73
76
101
100
109
185
98
150
57
55
52
50
74
98
149
103
143
144
188
75
93
47
101
50
147
74
88
212
147
82
271
70
95
74
86
68
205
121
110
141
202
129
138
92
98
24
77
99
150
166
143
109
218
233
86
182
53
144
135
110
102
142
166
200
101
86
102
141
14
199
99
189
200
111
140
219
120
150
110
105
76
86
119
118
159
166
109
86
146
66
236
66
279
59
102
102
77
164
113
103
104
112
222
62
140
73
87
114
63
121
137
114
112
207
81
122
98
51
86
100
81
82
81
94
184
278
68
116
44
59
53
48
53
72
48
127
83
153
80
73
39
68
52
90
68
96
97
77
112
35
83
54
62
38
42
53
98
72
92
115
81
36
88
76
43
56
85
60
38
43
71
36
92
61
52
42
73
42
65
77
130
63
75
80
91
151
74
41
70
85
55
80
58
66
67
91
47
45
64
61
39
62
44
72
85
78
42
82
58
70
50
62
54
63
74
75
85
46
80
98
95
47
52
100
79
77
79
103
82
88
71
76
72
116
84
73
86
116
54
90
67
92
68
103
67
79
68
92
111
98
73
88
84
94
65
130
56
127
60
86
177
123
76
73
107
83
93
114
133
69
98
88
112
77
85
62
47
51
126
104
82
106
90
132
82
129
50
102
120
76
91
177
114
61
74
93
75
80
73
44
74
94
110
46
80
59
44
61
88
72
39
108
61
162
56
96
35
61
126
103
80
36
99
106
83
221
104
68
24
49
43
112
60
57
65
79
93
152
55
68
66
35
101
47
98
54
85
41
128
98
50
46
51
46
93
74
68
72
61
77
64
72
29
34
81
55
37
62
77
59
56
103
67
44
61
22
68
57
51
50
59
116
35
83
45
45
20
42
67
42
70
54
87
42
101
69
78
50
44
35
78
81
79
61
61
44
116
84
42
68
37
30
55
70
99
47
43
83
96
21
49
63
75
47
82
104
54
57
70
67
89
101
39
44
51
77
80
130
68
74
67
73
82
48
37
53
58
66
109
59
61
73
108
80
81
34
45
62
133
97
135
38
87
94
70
48
56
41
51
58
35
88
177
30
81
83
113
39
33
55
106
56
47
244
132
66
64
76
50
76
38
34
136
143
176
205
41
104
103
86
104
57
51
185
160
86
235
192
120
60
46
83
87
56
50
198
82
127
292
188
59
121
78
106
78
60
115
167
63
238
235
84
155
47
87
160
79
60
233
236
63
227
284
137
110
101
73
198
27
99
240
121
206
294
198
184
117
73
116
127
47
223
278
76
232
184
125
233
112
107
187
167
62
219
228
95
293
278
265
244
102
129
192
56
128
215
142
223
208
126
218
133
59
174
152
31
184
295
64
377
284
82
268
68
122
221
103
70
197
248
145
276
223
227
323
102
153
127
45
120
205
104
231
251
211
289
225
78
247
221
53
175
295
94
235
238
220
245
99
99
163
150
106
285
210
173
258
186
183
235
68
169
184
53
128
244
71
223
212
137
278
205
84
218
227
59
185
283
66
308
166
171
230
92
129
205
189
77
239
126
176
313
134
271
240
47
162
251
86
207
202
64
228
267
56
274
89
60
231
180
50
232
277
65
211
203
164
288
104
105
198
93
85
173
78
143
242
165
232
195
73
192
135
57
201
323
73
206
242
83
272
88
61
133
112
39
225
138
88
279
157
299
203
54
93
184
32
53
191
94
137
200
103
231
194
49
98
86
52
124
180
55
145
104
292
201
59
61
161
40
38
163
80
109
133
99
259
167
40
91
156
21
37
136
104
116
135
66
235
152
22
93
69
29
92
100
85
82
92
299
190
45
43
56
43
81
58
90
83
106
88
288
177
49
54
70
24
34
88
68
81
59
73
163
56
43
37
63
30
63
68
45
61
99
58
end of experiment